Workbook

Sheet 프로젝트WBS
B1: 물류 분류 자동화 디지털 트윈 | L1: 실적기준일 : | M1: 46322 | U1: SPI | V1: =V5/T5 -> 0.35833333 | W1: =IF(V1<0.75,"(위험)",IF(V1<0.85,"(경고)",IF(V1<0.95,"(주의)","(양호)"))) -> (위험)
B3: 단계 | F3: TASK | H3: 담당 | K3: 산출물 | L3: 계획 시작일 | M3: 예상 완료일 | N3: 실제 시작일 | O3: 실제 완료(예정)일 | P3: 계획 기간 | Q3: 실제 기간 | R3: 계획 진행 | S3: 실제 진행 | T3: 계획 완료율 | U3: 작업 완료율 | V3: 프로젝트 실적 | X3: 일정
H4: A | I4: B | J4: C | V4: 진척율 | W4: 달성율 | X4: 26. 6월 | AH4: 26. 7월 | BE4: 26. 8월 | BZ4: 26. 9월 | CU4: 26. 10월 | DQ4: 26. 11월 | EN4: 26. 12월
C5: 가중치 | D5: 수행단계 | L5: =MIN(L6:L44) -> 46322 | M5: =MAX(M6:M44) -> 46331 | N5: =MIN(N6:N44) -> 46322 | O5: =MAX(O6:O44) -> 46322 | P5: =P45 -> 43 | Q5: =Q45 -> 2 | R5: =R45 -> 4 | S5: =S45 -> 2 | T5: =T45 -> 0.093023256 | U5: =U45 -> 1 | V5: =(AVERAGE(V6:V11)*C6)+(AVERAGE(V12:V16)*C12)+(AVERAGE(V17:V31)*C17)+(AVERAGE(V32:V37)*C32)+(AVERAGE(V38:V43)*C38) -> 0.033333333 | W5: =V5-T5 -> -0.059689922 | X5: 46195 | Y5: 46196 | Z5: 46197 | AA5: 46198 | AB5: 46199 | AC5: 46202 | AD5: 46203 | AE5: 46204 | AF5: 46205 | AG5: 46206 | AH5: 46209 | AI5: 46210 | AJ5: 46211 | AK5: 46212 | AL5: 46213 | AM5: 46216 | AN5: 46217 | AO5: 46218 | AP5: 46219 | AQ5: 46220 | AR5: 46223 | AS5: 46224 | AT5: 46225 | AU5: 46226 | AV5: 46227 | AW5: 46230 | AX5: 46231 | AY5: 46232 | AZ5: 46233 | BA5: 46234 | BB5: 46237 | BC5: 46238 | BD5: 46239 | BE5: 46240 | BF5: 46241 | BG5: 46244 | BH5: 46245 | BI5: 46246 | BJ5: 46247 | BK5: 46248 | BL5: 46251 | BM5: 46252 | BN5: 46253 | BO5: 46254 | BP5: 46255 | BQ5: 46258 | BR5: 46259 | BS5: 46260 | BT5: 46261 | BU5: 46262 | BV5: 46265 | BW5: 46266 | BX5: 46267 | BY5: 46268 | BZ5: 46269 | CA5: 46272 | CB5: 46273 | CC5: 46274 | CD5: 46275 | CE5: 46276 | CF5: 46279 | CG5: 46280 | CH5: 46281 | CI5: 46282 | CJ5: 46283 | CK5: 46286 | CL5: 46287 | CM5: 46288 | CN5: 46289 | CO5: 46290 | CP5: 46293 | CQ5: 46294 | CR5: 46295 | CS5: 46296 | CT5: 46297 | CU5: 46300 | CV5: 46301 | CW5: 46302 | CX5: 46303 | CY5: 46304 | CZ5: 46307 | DA5: 46308 | DB5: 46309 | DC5: 46310 | DD5: 46311 | DE5: 46314 | DF5: 46315 | DG5: 46316 | DH5: 46317 | DI5: 46318 | DJ5: 46321 | DK5: 46322 | DL5: 46323 | DM5: 46324 | DN5: 46325 | DO5: 46328 | DP5: 46329 | DQ5: 46330 | DR5: 46331 | DS5: 46332 | DT5: 46335 | DU5: 46336 | DV5: 46337 | DW5: 46338 | DX5: 46339 | DY5: 46342 | DZ5: 46343 | EA5: 46344 | EB5: 46345 | EC5: 46346 | ED5: 46349 | EE5: 46350 | EF5: 46351 | EG5: 46352 | EH5: 46353 | EI5: 46356 | EJ5: 46357 | EK5: 46358 | EL5: 46359 | EM5: 46360 | EN5: 46363 | EO5: 46364 | EP5: 46365 | EQ5: 46366 | ER5: 46367 | ES5: 46370 | ET5: 46371 | EU5: 46372 | EV5: 46373 | EW5: 46374 | EX5: 46377 | EY5: 46378 | EZ5: 46379 | FA5: 46380 | FB5: 46381 | FC5: 46384 | FD5: 46385 | FE5: 46386 | FF5: 46387 | FG5: 46388
B6: 1 | C6: 0.1 | D6: 준비/분석 | F6: 한 장 기획표 작성·멘토 피드백 반영 | H6: 정지훈 | I6: 박봉현 | K6: 한 장 기획표, 피드백 반영표 | L6: 46322 | M6: 46322 | N6: 46322 | O6: 46322 | P6: =NETWORKDAYS(L6,M6,휴일!$A$2:$A$8) -> 1 | Q6: =IF(NETWORKDAYS(N6,O6,휴일!$A$2:$A$8)<0,"",NETWORKDAYS(N6,O6,휴일!$A$2:$A$8)) -> 1 | R6: =IFERROR(IF(M6>=$M$1,IF(NETWORKDAYS(L6,$M$1,휴일!$A$2:$A$8)>0,NETWORKDAYS(L6,$M$1,휴일!$A$2:$A$8),""),NETWORKDAYS(L6,M6,휴일!$A$2:$A$8)),"") -> 1 | S6: =IF(IFERROR(IF(O6>=$M$1,IF(NETWORKDAYS(N6,$M$1,휴일!$A$2:$A$8)>0,NETWORKDAYS(N6,$M$1,휴일!$A$2:$A$8),""),NETWORKDAYS(N6,O6,휴일!$A$2:$A$8)),"")<0,"",IFERROR(IF(O6>=$M$1,IF(NETWORKDAYS(N6,$M$1,휴일!$A$2:$A$8)>0,NETWORKDAYS(N6,$M$1,휴일!$A$2:$A$8),""),NETWORKDAYS(N6,O6,휴일!$A$2:$A$8)),"")) -> 1 | T6: =IFERROR(R6/P6,0) -> 1 | U6: =IFERROR(S6/Q6,0) -> 1 | V6: =IF(OR(ISBLANK(S6),ISBLANK(P6),S6<=0,P6<=0),0,IF(S6="",0,1-(S6-P6)/P6)) -> 1 | W6: =V6-T6 -> 0
F7: SRS 작성 (요구사항 ID·검증 기준 확정) | H7: 정지훈 | K7: SRS v1.2 | L7: 46322 | M7: 46322 | N7: 46322 | O7: 46322 | P7: =NETWORKDAYS(L7,M7,휴일!$A$2:$A$8) -> 1 | Q7: =IF(NETWORKDAYS(N7,O7,휴일!$A$2:$A$8)<0,"",NETWORKDAYS(N7,O7,휴일!$A$2:$A$8)) -> 1 | R7: =IFERROR(IF(M7>=$M$1,IF(NETWORKDAYS(L7,$M$1,휴일!$A$2:$A$8)>0,NETWORKDAYS(L7,$M$1,휴일!$A$2:$A$8),""),NETWORKDAYS(L7,M7,휴일!$A$2:$A$8)),"") -> 1 | S7: =IF(IFERROR(IF(O7>=$M$1,IF(NETWORKDAYS(N7,$M$1,휴일!$A$2:$A$8)>0,NETWORKDAYS(N7,$M$1,휴일!$A$2:$A$8),""),NETWORKDAYS(N7,O7,휴일!$A$2:$A$8)),"")<0,"",IFERROR(IF(O7>=$M$1,IF(NETWORKDAYS(N7,$M$1,휴일!$A$2:$A$8)>0,NETWORKDAYS(N7,$M$1,휴일!$A$2:$A$8),""),NETWORKDAYS(N7,O7,휴일!$A$2:$A$8)),"")) -> 1 | T7: =IFERROR(R7/P7,0) -> 1 | U7: =IFERROR(S7/Q7,0) -> 1 | V7: =IF(OR(ISBLANK(S7),ISBLANK(P7),S7<=0,P7<=0),0,IF(S7="",0,1-(S7-P7)/P7)) -> 1 | W7: =V7-T7 -> 0
F8: Unity 프로젝트·패키지 환경 세팅 (ML-Agents 4.1.0, URDF Importer) | H8: 박봉현 | K8: 프로젝트 파일(.unity) | L8: 46322 | M8: 46323 | P8: =NETWORKDAYS(L8,M8,휴일!$A$2:$A$8) -> 2 | Q8: =IF(NETWORKDAYS(N8,O8,휴일!$A$2:$A$8)<0,"",NETWORKDAYS(N8,O8,휴일!$A$2:$A$8)) -> 0 | R8: =IFERROR(IF(M8>=$M$1,IF(NETWORKDAYS(L8,$M$1,휴일!$A$2:$A$8)>0,NETWORKDAYS(L8,$M$1,휴일!$A$2:$A$8),""),NETWORKDAYS(L8,M8,휴일!$A$2:$A$8)),"") -> 1 | S8: =IF(IFERROR(IF(O8>=$M$1,IF(NETWORKDAYS(N8,$M$1,휴일!$A$2:$A$8)>0,NETWORKDAYS(N8,$M$1,휴일!$A$2:$A$8),""),NETWORKDAYS(N8,O8,휴일!$A$2:$A$8)),"")<0,"",IFERROR(IF(O8>=$M$1,IF(NETWORKDAYS(N8,$M$1,휴일!$A$2:$A$8)>0,NETWORKDAYS(N8,$M$1,휴일!$A$2:$A$8),""),NETWORKDAYS(N8,O8,휴일!$A$2:$A$8)),"")) -> 0 | T8: =IFERROR(R8/P8,0) -> 0.5 | U8: =IFERROR(S8/Q8,0) -> 0 | V8: =IF(OR(ISBLANK(S8),ISBLANK(P8),S8<=0,P8<=0),0,IF(S8="",0,1-(S8-P8)/P8)) -> 0 | W8: =V8-T8 -> -0.5
F9: FR5 URDF·상자/컨베이어/AGV Asset 확보 | H9: 문강호 | K9: Asset 목록 | L9: 46322 | M9: 46323 | P9: =NETWORKDAYS(L9,M9,휴일!$A$2:$A$8) -> 2 | Q9: =IF(NETWORKDAYS(N9,O9,휴일!$A$2:$A$8)<0,"",NETWORKDAYS(N9,O9,휴일!$A$2:$A$8)) -> 0 | R9: =IFERROR(IF(M9>=$M$1,IF(NETWORKDAYS(L9,$M$1,휴일!$A$2:$A$8)>0,NETWORKDAYS(L9,$M$1,휴일!$A$2:$A$8),""),NETWORKDAYS(L9,M9,휴일!$A$2:$A$8)),"") -> 1 | S9: =IF(IFERROR(IF(O9>=$M$1,IF(NETWORKDAYS(N9,$M$1,휴일!$A$2:$A$8)>0,NETWORKDAYS(N9,$M$1,휴일!$A$2:$A$8),""),NETWORKDAYS(N9,O9,휴일!$A$2:$A$8)),"")<0,"",IFERROR(IF(O9>=$M$1,IF(NETWORKDAYS(N9,$M$1,휴일!$A$2:$A$8)>0,NETWORKDAYS(N9,$M$1,휴일!$A$2:$A$8),""),NETWORKDAYS(N9,O9,휴일!$A$2:$A$8)),"")) -> 0 | T9: =IFERROR(R9/P9,0) -> 0.5 | U9: =IFERROR(S9/Q9,0) -> 0 | V9: =IF(OR(ISBLANK(S9),ISBLANK(P9),S9<=0,P9<=0),0,IF(S9="",0,1-(S9-P9)/P9)) -> 0 | W9: =V9-T9 -> -0.5
F10: 송장 라벨 텍스처·투입 데이터 준비 (지역 코드 11/22/33) | H10: 문강호 | K10: 라벨 텍스처, 투입 목록 | L10: 46323 | M10: 46323 | P10: =NETWORKDAYS(L10,M10,휴일!$A$2:$A$8) -> 1 | Q10: =IF(NETWORKDAYS(N10,O10,휴일!$A$2:$A$8)<0,"",NETWORKDAYS(N10,O10,휴일!$A$2:$A$8)) -> 0 | R10: =IFERROR(IF(M10>=$M$1,IF(NETWORKDAYS(L10,$M$1,휴일!$A$2:$A$8)>0,NETWORKDAYS(L10,$M$1,휴일!$A$2:$A$8),""),NETWORKDAYS(L10,M10,휴일!$A$2:$A$8)),"") | S10: =IF(IFERROR(IF(O10>=$M$1,IF(NETWORKDAYS(N10,$M$1,휴일!$A$2:$A$8)>0,NETWORKDAYS(N10,$M$1,휴일!$A$2:$A$8),""),NETWORKDAYS(N10,O10,휴일!$A$2:$A$8)),"")<0,"",IFERROR(IF(O10>=$M$1,IF(NETWORKDAYS(N10,$M$1,휴일!$A$2:$A$8)>0,NETWORKDAYS(N10,$M$1,휴일!$A$2:$A$8),""),NETWORKDAYS(N10,O10,휴일!$A$2:$A$8)),"")) -> 0 | T10: =IFERROR(R10/P10,0) -> 0 | U10: =IFERROR(S10/Q10,0) -> 0 | V10: =IF(OR(ISBLANK(S10),ISBLANK(P10),S10<=0,P10<=0),0,IF(S10="",0,1-(S10-P10)/P10)) -> 0 | W10: =V10-T10 -> 0
P11: =NETWORKDAYS(L11,M11,휴일!$A$2:$A$8) -> 0 | Q11: =IF(NETWORKDAYS(N11,O11,휴일!$A$2:$A$8)<0,"",NETWORKDAYS(N11,O11,휴일!$A$2:$A$8)) -> 0 | R11: =IFERROR(IF(M11>=$M$1,IF(NETWORKDAYS(L11,$M$1,휴일!$A$2:$A$8)>0,NETWORKDAYS(L11,$M$1,휴일!$A$2:$A$8),""),NETWORKDAYS(L11,M11,휴일!$A$2:$A$8)),"") -> 0 | S11: =IF(IFERROR(IF(O11>=$M$1,IF(NETWORKDAYS(N11,$M$1,휴일!$A$2:$A$8)>0,NETWORKDAYS(N11,$M$1,휴일!$A$2:$A$8),""),NETWORKDAYS(N11,O11,휴일!$A$2:$A$8)),"")<0,"",IFERROR(IF(O11>=$M$1,IF(NETWORKDAYS(N11,$M$1,휴일!$A$2:$A$8)>0,NETWORKDAYS(N11,$M$1,휴일!$A$2:$A$8),""),NETWORKDAYS(N11,O11,휴일!$A$2:$A$8)),"")) -> 0 | T11: =IFERROR(R11/P11,0) -> 0 | U11: =IFERROR(S11/Q11,0) -> 0 | V11: =IF(OR(ISBLANK(S11),ISBLANK(P11),S11<=0,P11<=0),0,IF(S11="",0,1-(S11-P11)/P11)) -> 0 | W11: =V11-T11 -> 0
B12: 2 | C12: 0.15 | D12: 설계 | F12: 공정 씬 레이아웃 설계 (5개 스테이션 배치) | H12: 정지훈 | K12: 씬 구성안 | L12: 46323 | M12: 46323 | P12: =NETWORKDAYS(L12,M12,휴일!$A$2:$A$8) -> 1 | Q12: =IF(NETWORKDAYS(N12,O12,휴일!$A$2:$A$8)<0,"",NETWORKDAYS(N12,O12,휴일!$A$2:$A$8)) -> 0 | R12: =IFERROR(IF(M12>=$M$1,IF(NETWORKDAYS(L12,$M$1,휴일!$A$2:$A$8)>0,NETWORKDAYS(L12,$M$1,휴일!$A$2:$A$8),""),NETWORKDAYS(L12,M12,휴일!$A$2:$A$8)),"") | S12: =IF(IFERROR(IF(O12>=$M$1,IF(NETWORKDAYS(N12,$M$1,휴일!$A$2:$A$8)>0,NETWORKDAYS(N12,$M$1,휴일!$A$2:$A$8),""),NETWORKDAYS(N12,O12,휴일!$A$2:$A$8)),"")<0,"",IFERROR(IF(O12>=$M$1,IF(NETWORKDAYS(N12,$M$1,휴일!$A$2:$A$8)>0,NETWORKDAYS(N12,$M$1,휴일!$A$2:$A$8),""),NETWORKDAYS(N12,O12,휴일!$A$2:$A$8)),"")) -> 0 | T12: =IFERROR(R12/P12,0) -> 0 | U12: =IFERROR(S12/Q12,0) -> 0 | V12: =IF(OR(ISBLANK(S12),ISBLANK(P12),S12<=0,P12<=0),0,IF(S12="",0,1-(S12-P12)/P12)) -> 0 | W12: =V12-T12 -> 0
F13: 송장 번호 체계·검증 규칙 설계 (5자리, 지역 코드 11/22/33) | H13: 정지훈 | K13: 규칙 정의서 | L13: 46323 | M13: 46323 | P13: =NETWORKDAYS(L13,M13,휴일!$A$2:$A$8) -> 1 | Q13: =IF(NETWORKDAYS(N13,O13,휴일!$A$2:$A$8)<0,"",NETWORKDAYS(N13,O13,휴일!$A$2:$A$8)) -> 0 | R13: =IFERROR(IF(M13>=$M$1,IF(NETWORKDAYS(L13,$M$1,휴일!$A$2:$A$8)>0,NETWORKDAYS(L13,$M$1,휴일!$A$2:$A$8),""),NETWORKDAYS(L13,M13,휴일!$A$2:$A$8)),"") | S13: =IF(IFERROR(IF(O13>=$M$1,IF(NETWORKDAYS(N13,$M$1,휴일!$A$2:$A$8)>0,NETWORKDAYS(N13,$M$1,휴일!$A$2:$A$8),""),NETWORKDAYS(N13,O13,휴일!$A$2:$A$8)),"")<0,"",IFERROR(IF(O13>=$M$1,IF(NETWORKDAYS(N13,$M$1,휴일!$A$2:$A$8)>0,NETWORKDAYS(N13,$M$1,휴일!$A$2:$A$8),""),NETWORKDAYS(N13,O13,휴일!$A$2:$A$8)),"")) -> 0 | T13: =IFERROR(R13/P13,0) -> 0 | U13: =IFERROR(S13/Q13,0) -> 0 | V13: =IF(OR(ISBLANK(S13),ISBLANK(P13),S13<=0,P13<=0),0,IF(S13="",0,1-(S13-P13)/P13)) -> 0 | W13: =V13-T13 -> 0
F14: 로봇암 자세 교정 동작 설계 (IK·부착 방식) | H14: 박봉현 | K14: 동작 설계안 | L14: 46323 | M14: 46323 | P14: =NETWORKDAYS(L14,M14,휴일!$A$2:$A$8) -> 1 | Q14: =IF(NETWORKDAYS(N14,O14,휴일!$A$2:$A$8)<0,"",NETWORKDAYS(N14,O14,휴일!$A$2:$A$8)) -> 0 | R14: =IFERROR(IF(M14>=$M$1,IF(NETWORKDAYS(L14,$M$1,휴일!$A$2:$A$8)>0,NETWORKDAYS(L14,$M$1,휴일!$A$2:$A$8),""),NETWORKDAYS(L14,M14,휴일!$A$2:$A$8)),"") | S14: =IF(IFERROR(IF(O14>=$M$1,IF(NETWORKDAYS(N14,$M$1,휴일!$A$2:$A$8)>0,NETWORKDAYS(N14,$M$1,휴일!$A$2:$A$8),""),NETWORKDAYS(N14,O14,휴일!$A$2:$A$8)),"")<0,"",IFERROR(IF(O14>=$M$1,IF(NETWORKDAYS(N14,$M$1,휴일!$A$2:$A$8)>0,NETWORKDAYS(N14,$M$1,휴일!$A$2:$A$8),""),NETWORKDAYS(N14,O14,휴일!$A$2:$A$8)),"")) -> 0 | T14: =IFERROR(R14/P14,0) -> 0 | U14: =IFERROR(S14/Q14,0) -> 0 | V14: =IF(OR(ISBLANK(S14),ISBLANK(P14),S14<=0,P14<=0),0,IF(S14="",0,1-(S14-P14)/P14)) -> 0 | W14: =V14-T14 -> 0
F15: 대시보드·운전 제어 UI 설계 | H15: 문강호 | K15: UI 구성안 | L15: 46323 | M15: 46323 | P15: =NETWORKDAYS(L15,M15,휴일!$A$2:$A$8) -> 1 | Q15: =IF(NETWORKDAYS(N15,O15,휴일!$A$2:$A$8)<0,"",NETWORKDAYS(N15,O15,휴일!$A$2:$A$8)) -> 0 | R15: =IFERROR(IF(M15>=$M$1,IF(NETWORKDAYS(L15,$M$1,휴일!$A$2:$A$8)>0,NETWORKDAYS(L15,$M$1,휴일!$A$2:$A$8),""),NETWORKDAYS(L15,M15,휴일!$A$2:$A$8)),"") | S15: =IF(IFERROR(IF(O15>=$M$1,IF(NETWORKDAYS(N15,$M$1,휴일!$A$2:$A$8)>0,NETWORKDAYS(N15,$M$1,휴일!$A$2:$A$8),""),NETWORKDAYS(N15,O15,휴일!$A$2:$A$8)),"")<0,"",IFERROR(IF(O15>=$M$1,IF(NETWORKDAYS(N15,$M$1,휴일!$A$2:$A$8)>0,NETWORKDAYS(N15,$M$1,휴일!$A$2:$A$8),""),NETWORKDAYS(N15,O15,휴일!$A$2:$A$8)),"")) -> 0 | T15: =IFERROR(R15/P15,0) -> 0 | U15: =IFERROR(S15/Q15,0) -> 0 | V15: =IF(OR(ISBLANK(S15),ISBLANK(P15),S15<=0,P15<=0),0,IF(S15="",0,1-(S15-P15)/P15)) -> 0 | W15: =V15-T15 -> 0
F16: ML 관측·보상 설계 (자세 교정·목적지 배치) | H16: 박봉현 | K16: 학습 설계안 | L16: 46324 | M16: 46324 | P16: =NETWORKDAYS(L16,M16,휴일!$A$2:$A$8) -> 1 | Q16: =IF(NETWORKDAYS(N16,O16,휴일!$A$2:$A$8)<0,"",NETWORKDAYS(N16,O16,휴일!$A$2:$A$8)) -> 0 | R16: =IFERROR(IF(M16>=$M$1,IF(NETWORKDAYS(L16,$M$1,휴일!$A$2:$A$8)>0,NETWORKDAYS(L16,$M$1,휴일!$A$2:$A$8),""),NETWORKDAYS(L16,M16,휴일!$A$2:$A$8)),"") | S16: =IF(IFERROR(IF(O16>=$M$1,IF(NETWORKDAYS(N16,$M$1,휴일!$A$2:$A$8)>0,NETWORKDAYS(N16,$M$1,휴일!$A$2:$A$8),""),NETWORKDAYS(N16,O16,휴일!$A$2:$A$8)),"")<0,"",IFERROR(IF(O16>=$M$1,IF(NETWORKDAYS(N16,$M$1,휴일!$A$2:$A$8)>0,NETWORKDAYS(N16,$M$1,휴일!$A$2:$A$8),""),NETWORKDAYS(N16,O16,휴일!$A$2:$A$8)),"")) -> 0 | T16: =IFERROR(R16/P16,0) -> 0 | U16: =IFERROR(S16/Q16,0) -> 0 | V16: =IF(OR(ISBLANK(S16),ISBLANK(P16),S16<=0,P16<=0),0,IF(S16="",0,1-(S16-P16)/P16)) -> 0 | W16: =V16-T16 -> 0
B17: 3 | C17: 0.4 | D17: 구현 | F17: 공정 씬 구성·FR5 로봇암 2대 배치·적재 대기점 설치 | H17: 정지훈 | K17: 공정 씬 | L17: 46323 | M17: 46323 | P17: =NETWORKDAYS(L17,M17,휴일!$A$2:$A$8) -> 1 | Q17: =IF(NETWORKDAYS(N17,O17,휴일!$A$2:$A$8)<0,"",NETWORKDAYS(N17,O17,휴일!$A$2:$A$8)) -> 0 | R17: =IFERROR(IF(M17>=$M$1,IF(NETWORKDAYS(L17,$M$1,휴일!$A$2:$A$8)>0,NETWORKDAYS(L17,$M$1,휴일!$A$2:$A$8),""),NETWORKDAYS(L17,M17,휴일!$A$2:$A$8)),"") | S17: =IF(IFERROR(IF(O17>=$M$1,IF(NETWORKDAYS(N17,$M$1,휴일!$A$2:$A$8)>0,NETWORKDAYS(N17,$M$1,휴일!$A$2:$A$8),""),NETWORKDAYS(N17,O17,휴일!$A$2:$A$8)),"")<0,"",IFERROR(IF(O17>=$M$1,IF(NETWORKDAYS(N17,$M$1,휴일!$A$2:$A$8)>0,NETWORKDAYS(N17,$M$1,휴일!$A$2:$A$8),""),NETWORKDAYS(N17,O17,휴일!$A$2:$A$8)),"")) -> 0 | T17: =IFERROR(R17/P17,0) -> 0 | U17: =IFERROR(S17/Q17,0) -> 0 | V17: =IF(OR(ISBLANK(S17),ISBLANK(P17),S17<=0,P17<=0),0,IF(S17="",0,1-(S17-P17)/P17)) -> 0 | W17: =V17-T17 -> 0
F18: 상자 생성·송장면 방향 배정 (FR-01) | H18: 문강호 | K18: 상자 생성 스크립트 | L18: 46323 | M18: 46324 | P18: =NETWORKDAYS(L18,M18,휴일!$A$2:$A$8) -> 2 | Q18: =IF(NETWORKDAYS(N18,O18,휴일!$A$2:$A$8)<0,"",NETWORKDAYS(N18,O18,휴일!$A$2:$A$8)) -> 0 | R18: =IFERROR(IF(M18>=$M$1,IF(NETWORKDAYS(L18,$M$1,휴일!$A$2:$A$8)>0,NETWORKDAYS(L18,$M$1,휴일!$A$2:$A$8),""),NETWORKDAYS(L18,M18,휴일!$A$2:$A$8)),"") | S18: =IF(IFERROR(IF(O18>=$M$1,IF(NETWORKDAYS(N18,$M$1,휴일!$A$2:$A$8)>0,NETWORKDAYS(N18,$M$1,휴일!$A$2:$A$8),""),NETWORKDAYS(N18,O18,휴일!$A$2:$A$8)),"")<0,"",IFERROR(IF(O18>=$M$1,IF(NETWORKDAYS(N18,$M$1,휴일!$A$2:$A$8)>0,NETWORKDAYS(N18,$M$1,휴일!$A$2:$A$8),""),NETWORKDAYS(N18,O18,휴일!$A$2:$A$8)),"")) -> 0 | T18: =IFERROR(R18/P18,0) -> 0 | U18: =IFERROR(S18/Q18,0) -> 0 | V18: =IF(OR(ISBLANK(S18),ISBLANK(P18),S18<=0,P18<=0),0,IF(S18="",0,1-(S18-P18)/P18)) -> 0 | W18: =V18-T18 -> 0
F19: 컨베이어 이송·스캔 대기점 정지 (FR-02) | H19: 문강호 | K19: 컨베이어·스토퍼 스크립트 | L19: 46324 | M19: 46324 | P19: =NETWORKDAYS(L19,M19,휴일!$A$2:$A$8) -> 1 | Q19: =IF(NETWORKDAYS(N19,O19,휴일!$A$2:$A$8)<0,"",NETWORKDAYS(N19,O19,휴일!$A$2:$A$8)) -> 0 | R19: =IFERROR(IF(M19>=$M$1,IF(NETWORKDAYS(L19,$M$1,휴일!$A$2:$A$8)>0,NETWORKDAYS(L19,$M$1,휴일!$A$2:$A$8),""),NETWORKDAYS(L19,M19,휴일!$A$2:$A$8)),"") | S19: =IF(IFERROR(IF(O19>=$M$1,IF(NETWORKDAYS(N19,$M$1,휴일!$A$2:$A$8)>0,NETWORKDAYS(N19,$M$1,휴일!$A$2:$A$8),""),NETWORKDAYS(N19,O19,휴일!$A$2:$A$8)),"")<0,"",IFERROR(IF(O19>=$M$1,IF(NETWORKDAYS(N19,$M$1,휴일!$A$2:$A$8)>0,NETWORKDAYS(N19,$M$1,휴일!$A$2:$A$8),""),NETWORKDAYS(N19,O19,휴일!$A$2:$A$8)),"")) -> 0 | T19: =IFERROR(R19/P19,0) -> 0 | U19: =IFERROR(S19/Q19,0) -> 0 | V19: =IF(OR(ISBLANK(S19),ISBLANK(P19),S19<=0,P19<=0),0,IF(S19="",0,1-(S19-P19)/P19)) -> 0 | W19: =V19-T19 -> 0
F20: 판정 카메라 5대 배치·학습 이미지 자동 생성 (FR-03 ①) | H20: 정지훈 | K20: 카메라 리그, 학습 이미지셋 | L20: 46324 | M20: 46324 | P20: =NETWORKDAYS(L20,M20,휴일!$A$2:$A$8) -> 1 | Q20: =IF(NETWORKDAYS(N20,O20,휴일!$A$2:$A$8)<0,"",NETWORKDAYS(N20,O20,휴일!$A$2:$A$8)) -> 0 | R20: =IFERROR(IF(M20>=$M$1,IF(NETWORKDAYS(L20,$M$1,휴일!$A$2:$A$8)>0,NETWORKDAYS(L20,$M$1,휴일!$A$2:$A$8),""),NETWORKDAYS(L20,M20,휴일!$A$2:$A$8)),"") | S20: =IF(IFERROR(IF(O20>=$M$1,IF(NETWORKDAYS(N20,$M$1,휴일!$A$2:$A$8)>0,NETWORKDAYS(N20,$M$1,휴일!$A$2:$A$8),""),NETWORKDAYS(N20,O20,휴일!$A$2:$A$8)),"")<0,"",IFERROR(IF(O20>=$M$1,IF(NETWORKDAYS(N20,$M$1,휴일!$A$2:$A$8)>0,NETWORKDAYS(N20,$M$1,휴일!$A$2:$A$8),""),NETWORKDAYS(N20,O20,휴일!$A$2:$A$8)),"")) -> 0 | T20: =IFERROR(R20/P20,0) -> 0 | U20: =IFERROR(S20/Q20,0) -> 0 | V20: =IF(OR(ISBLANK(S20),ISBLANK(P20),S20<=0,P20<=0),0,IF(S20="",0,1-(S20-P20)/P20)) -> 0 | W20: =V20-T20 -> 0
F21: CNN 학습·ONNX 모델 내보내기 (FR-03 ②) | H21: 정지훈 | K21: ONNX 모델 파일, 학습 로그 | L21: 46325 | M21: 46325 | P21: =NETWORKDAYS(L21,M21,휴일!$A$2:$A$8) -> 1 | Q21: =IF(NETWORKDAYS(N21,O21,휴일!$A$2:$A$8)<0,"",NETWORKDAYS(N21,O21,휴일!$A$2:$A$8)) -> 0 | R21: =IFERROR(IF(M21>=$M$1,IF(NETWORKDAYS(L21,$M$1,휴일!$A$2:$A$8)>0,NETWORKDAYS(L21,$M$1,휴일!$A$2:$A$8),""),NETWORKDAYS(L21,M21,휴일!$A$2:$A$8)),"") | S21: =IF(IFERROR(IF(O21>=$M$1,IF(NETWORKDAYS(N21,$M$1,휴일!$A$2:$A$8)>0,NETWORKDAYS(N21,$M$1,휴일!$A$2:$A$8),""),NETWORKDAYS(N21,O21,휴일!$A$2:$A$8)),"")<0,"",IFERROR(IF(O21>=$M$1,IF(NETWORKDAYS(N21,$M$1,휴일!$A$2:$A$8)>0,NETWORKDAYS(N21,$M$1,휴일!$A$2:$A$8),""),NETWORKDAYS(N21,O21,휴일!$A$2:$A$8)),"")) -> 0 | T21: =IFERROR(R21/P21,0) -> 0 | U21: =IFERROR(S21/Q21,0) -> 0 | V21: =IF(OR(ISBLANK(S21),ISBLANK(P21),S21<=0,P21<=0),0,IF(S21="",0,1-(S21-P21)/P21)) -> 0 | W21: =V21-T21 -> 0
F22: Inference Engine 연동·5면 판정→뒤집기 흐름 (FR-03 ③) | H22: 정지훈 | K22: 판정 모듈 | L22: 46328 | M22: 46328 | P22: =NETWORKDAYS(L22,M22,휴일!$A$2:$A$8) -> 1 | Q22: =IF(NETWORKDAYS(N22,O22,휴일!$A$2:$A$8)<0,"",NETWORKDAYS(N22,O22,휴일!$A$2:$A$8)) -> 0 | R22: =IFERROR(IF(M22>=$M$1,IF(NETWORKDAYS(L22,$M$1,휴일!$A$2:$A$8)>0,NETWORKDAYS(L22,$M$1,휴일!$A$2:$A$8),""),NETWORKDAYS(L22,M22,휴일!$A$2:$A$8)),"") | S22: =IF(IFERROR(IF(O22>=$M$1,IF(NETWORKDAYS(N22,$M$1,휴일!$A$2:$A$8)>0,NETWORKDAYS(N22,$M$1,휴일!$A$2:$A$8),""),NETWORKDAYS(N22,O22,휴일!$A$2:$A$8)),"")<0,"",IFERROR(IF(O22>=$M$1,IF(NETWORKDAYS(N22,$M$1,휴일!$A$2:$A$8)>0,NETWORKDAYS(N22,$M$1,휴일!$A$2:$A$8),""),NETWORKDAYS(N22,O22,휴일!$A$2:$A$8)),"")) -> 0 | T22: =IFERROR(R22/P22,0) -> 0 | U22: =IFERROR(S22/Q22,0) -> 0 | V22: =IF(OR(ISBLANK(S22),ISBLANK(P22),S22<=0,P22<=0),0,IF(S22="",0,1-(S22-P22)/P22)) -> 0 | W22: =V22-T22 -> 0
F23: 송장 번호 OCR 판독·숫자 규칙 검증 (FR-04, FR-07) | H23: 정지훈 | K23: OCR 모듈, 검증 스크립트 | L23: 46325 | M23: 46325 | P23: =NETWORKDAYS(L23,M23,휴일!$A$2:$A$8) -> 1 | Q23: =IF(NETWORKDAYS(N23,O23,휴일!$A$2:$A$8)<0,"",NETWORKDAYS(N23,O23,휴일!$A$2:$A$8)) -> 0 | R23: =IFERROR(IF(M23>=$M$1,IF(NETWORKDAYS(L23,$M$1,휴일!$A$2:$A$8)>0,NETWORKDAYS(L23,$M$1,휴일!$A$2:$A$8),""),NETWORKDAYS(L23,M23,휴일!$A$2:$A$8)),"") | S23: =IF(IFERROR(IF(O23>=$M$1,IF(NETWORKDAYS(N23,$M$1,휴일!$A$2:$A$8)>0,NETWORKDAYS(N23,$M$1,휴일!$A$2:$A$8),""),NETWORKDAYS(N23,O23,휴일!$A$2:$A$8)),"")<0,"",IFERROR(IF(O23>=$M$1,IF(NETWORKDAYS(N23,$M$1,휴일!$A$2:$A$8)>0,NETWORKDAYS(N23,$M$1,휴일!$A$2:$A$8),""),NETWORKDAYS(N23,O23,휴일!$A$2:$A$8)),"")) -> 0 | T23: =IFERROR(R23/P23,0) -> 0 | U23: =IFERROR(S23/Q23,0) -> 0 | V23: =IF(OR(ISBLANK(S23),ISBLANK(P23),S23<=0,P23<=0),0,IF(S23="",0,1-(S23-P23)/P23)) -> 0 | W23: =V23-T23 -> 0
F24: 교정 로봇암 자세 교정 (FR-05) | H24: 박봉현 | K24: 교정 스크립트 | L24: 46324 | M24: 46325 | P24: =NETWORKDAYS(L24,M24,휴일!$A$2:$A$8) -> 2 | Q24: =IF(NETWORKDAYS(N24,O24,휴일!$A$2:$A$8)<0,"",NETWORKDAYS(N24,O24,휴일!$A$2:$A$8)) -> 0 | R24: =IFERROR(IF(M24>=$M$1,IF(NETWORKDAYS(L24,$M$1,휴일!$A$2:$A$8)>0,NETWORKDAYS(L24,$M$1,휴일!$A$2:$A$8),""),NETWORKDAYS(L24,M24,휴일!$A$2:$A$8)),"") | S24: =IF(IFERROR(IF(O24>=$M$1,IF(NETWORKDAYS(N24,$M$1,휴일!$A$2:$A$8)>0,NETWORKDAYS(N24,$M$1,휴일!$A$2:$A$8),""),NETWORKDAYS(N24,O24,휴일!$A$2:$A$8)),"")<0,"",IFERROR(IF(O24>=$M$1,IF(NETWORKDAYS(N24,$M$1,휴일!$A$2:$A$8)>0,NETWORKDAYS(N24,$M$1,휴일!$A$2:$A$8),""),NETWORKDAYS(N24,O24,휴일!$A$2:$A$8)),"")) -> 0 | T24: =IFERROR(R24/P24,0) -> 0 | U24: =IFERROR(S24/Q24,0) -> 0 | V24: =IF(OR(ISBLANK(S24),ISBLANK(P24),S24<=0,P24<=0),0,IF(S24="",0,1-(S24-P24)/P24)) -> 0 | W24: =V24-T24 -> 0
F25: 재스캔 반복 종료 (FR-06) | H25: 박봉현 | K25: 재시도 제어 스크립트 | L25: 46325 | M25: 46325 | P25: =NETWORKDAYS(L25,M25,휴일!$A$2:$A$8) -> 1 | Q25: =IF(NETWORKDAYS(N25,O25,휴일!$A$2:$A$8)<0,"",NETWORKDAYS(N25,O25,휴일!$A$2:$A$8)) -> 0 | R25: =IFERROR(IF(M25>=$M$1,IF(NETWORKDAYS(L25,$M$1,휴일!$A$2:$A$8)>0,NETWORKDAYS(L25,$M$1,휴일!$A$2:$A$8),""),NETWORKDAYS(L25,M25,휴일!$A$2:$A$8)),"") | S25: =IF(IFERROR(IF(O25>=$M$1,IF(NETWORKDAYS(N25,$M$1,휴일!$A$2:$A$8)>0,NETWORKDAYS(N25,$M$1,휴일!$A$2:$A$8),""),NETWORKDAYS(N25,O25,휴일!$A$2:$A$8)),"")<0,"",IFERROR(IF(O25>=$M$1,IF(NETWORKDAYS(N25,$M$1,휴일!$A$2:$A$8)>0,NETWORKDAYS(N25,$M$1,휴일!$A$2:$A$8),""),NETWORKDAYS(N25,O25,휴일!$A$2:$A$8)),"")) -> 0 | T25: =IFERROR(R25/P25,0) -> 0 | U25: =IFERROR(S25/Q25,0) -> 0 | V25: =IF(OR(ISBLANK(S25),ISBLANK(P25),S25<=0,P25<=0),0,IF(S25="",0,1-(S25-P25)/P25)) -> 0 | W25: =V25-T25 -> 0
F26: 구간 이송·적재 대기점 정지 (FR-16) | H26: 문강호 | K26: 구간 이송 스크립트 | L26: 46325 | M26: 46325 | P26: =NETWORKDAYS(L26,M26,휴일!$A$2:$A$8) -> 1 | Q26: =IF(NETWORKDAYS(N26,O26,휴일!$A$2:$A$8)<0,"",NETWORKDAYS(N26,O26,휴일!$A$2:$A$8)) -> 0 | R26: =IFERROR(IF(M26>=$M$1,IF(NETWORKDAYS(L26,$M$1,휴일!$A$2:$A$8)>0,NETWORKDAYS(L26,$M$1,휴일!$A$2:$A$8),""),NETWORKDAYS(L26,M26,휴일!$A$2:$A$8)),"") | S26: =IF(IFERROR(IF(O26>=$M$1,IF(NETWORKDAYS(N26,$M$1,휴일!$A$2:$A$8)>0,NETWORKDAYS(N26,$M$1,휴일!$A$2:$A$8),""),NETWORKDAYS(N26,O26,휴일!$A$2:$A$8)),"")<0,"",IFERROR(IF(O26>=$M$1,IF(NETWORKDAYS(N26,$M$1,휴일!$A$2:$A$8)>0,NETWORKDAYS(N26,$M$1,휴일!$A$2:$A$8),""),NETWORKDAYS(N26,O26,휴일!$A$2:$A$8)),"")) -> 0 | T26: =IFERROR(R26/P26,0) -> 0 | U26: =IFERROR(S26/Q26,0) -> 0 | V26: =IF(OR(ISBLANK(S26),ISBLANK(P26),S26<=0,P26<=0),0,IF(S26="",0,1-(S26-P26)/P26)) -> 0 | W26: =V26-T26 -> 0
F27: 분류 로봇암 적재·예외 배출 (FR-08, FR-09) | H27: 박봉현 | I27: 문강호 | K27: 적재·예외 처리 스크립트 | L27: 46325 | M27: 46328 | P27: =NETWORKDAYS(L27,M27,휴일!$A$2:$A$8) -> 2 | Q27: =IF(NETWORKDAYS(N27,O27,휴일!$A$2:$A$8)<0,"",NETWORKDAYS(N27,O27,휴일!$A$2:$A$8)) -> 0 | R27: =IFERROR(IF(M27>=$M$1,IF(NETWORKDAYS(L27,$M$1,휴일!$A$2:$A$8)>0,NETWORKDAYS(L27,$M$1,휴일!$A$2:$A$8),""),NETWORKDAYS(L27,M27,휴일!$A$2:$A$8)),"") | S27: =IF(IFERROR(IF(O27>=$M$1,IF(NETWORKDAYS(N27,$M$1,휴일!$A$2:$A$8)>0,NETWORKDAYS(N27,$M$1,휴일!$A$2:$A$8),""),NETWORKDAYS(N27,O27,휴일!$A$2:$A$8)),"")<0,"",IFERROR(IF(O27>=$M$1,IF(NETWORKDAYS(N27,$M$1,휴일!$A$2:$A$8)>0,NETWORKDAYS(N27,$M$1,휴일!$A$2:$A$8),""),NETWORKDAYS(N27,O27,휴일!$A$2:$A$8)),"")) -> 0 | T27: =IFERROR(R27/P27,0) -> 0 | U27: =IFERROR(S27/Q27,0) -> 0 | V27: =IF(OR(ISBLANK(S27),ISBLANK(P27),S27<=0,P27<=0),0,IF(S27="",0,1-(S27-P27)/P27)) -> 0 | W27: =V27-T27 -> 0
F28: 공정 지표 대시보드·이상 상황 경고 (FR-10, FR-11) | H28: 문강호 | K28: 대시보드 UI | L28: 46328 | M28: 46328 | P28: =NETWORKDAYS(L28,M28,휴일!$A$2:$A$8) -> 1 | Q28: =IF(NETWORKDAYS(N28,O28,휴일!$A$2:$A$8)<0,"",NETWORKDAYS(N28,O28,휴일!$A$2:$A$8)) -> 0 | R28: =IFERROR(IF(M28>=$M$1,IF(NETWORKDAYS(L28,$M$1,휴일!$A$2:$A$8)>0,NETWORKDAYS(L28,$M$1,휴일!$A$2:$A$8),""),NETWORKDAYS(L28,M28,휴일!$A$2:$A$8)),"") | S28: =IF(IFERROR(IF(O28>=$M$1,IF(NETWORKDAYS(N28,$M$1,휴일!$A$2:$A$8)>0,NETWORKDAYS(N28,$M$1,휴일!$A$2:$A$8),""),NETWORKDAYS(N28,O28,휴일!$A$2:$A$8)),"")<0,"",IFERROR(IF(O28>=$M$1,IF(NETWORKDAYS(N28,$M$1,휴일!$A$2:$A$8)>0,NETWORKDAYS(N28,$M$1,휴일!$A$2:$A$8),""),NETWORKDAYS(N28,O28,휴일!$A$2:$A$8)),"")) -> 0 | T28: =IFERROR(R28/P28,0) -> 0 | U28: =IFERROR(S28/Q28,0) -> 0 | V28: =IF(OR(ISBLANK(S28),ISBLANK(P28),S28<=0,P28<=0),0,IF(S28="",0,1-(S28-P28)/P28)) -> 0 | W28: =V28-T28 -> 0
F29: 제어 방식 전환·학습 정책 적용 (FR-12, FR-14) | H29: 박봉현 | K29: 정책 연동 스크립트 | L29: 46328 | M29: 46328 | P29: =NETWORKDAYS(L29,M29,휴일!$A$2:$A$8) -> 1 | Q29: =IF(NETWORKDAYS(N29,O29,휴일!$A$2:$A$8)<0,"",NETWORKDAYS(N29,O29,휴일!$A$2:$A$8)) -> 0 | R29: =IFERROR(IF(M29>=$M$1,IF(NETWORKDAYS(L29,$M$1,휴일!$A$2:$A$8)>0,NETWORKDAYS(L29,$M$1,휴일!$A$2:$A$8),""),NETWORKDAYS(L29,M29,휴일!$A$2:$A$8)),"") | S29: =IF(IFERROR(IF(O29>=$M$1,IF(NETWORKDAYS(N29,$M$1,휴일!$A$2:$A$8)>0,NETWORKDAYS(N29,$M$1,휴일!$A$2:$A$8),""),NETWORKDAYS(N29,O29,휴일!$A$2:$A$8)),"")<0,"",IFERROR(IF(O29>=$M$1,IF(NETWORKDAYS(N29,$M$1,휴일!$A$2:$A$8)>0,NETWORKDAYS(N29,$M$1,휴일!$A$2:$A$8),""),NETWORKDAYS(N29,O29,휴일!$A$2:$A$8)),"")) -> 0 | T29: =IFERROR(R29/P29,0) -> 0 | U29: =IFERROR(S29/Q29,0) -> 0 | V29: =IF(OR(ISBLANK(S29),ISBLANK(P29),S29<=0,P29<=0),0,IF(S29="",0,1-(S29-P29)/P29)) -> 0 | W29: =V29-T29 -> 0
F30: 연속 투입·연속 분류 (FR-13) | H30: 문강호 | K30: 연속 운전 스크립트 | L30: 46328 | M30: 46328 | P30: =NETWORKDAYS(L30,M30,휴일!$A$2:$A$8) -> 1 | Q30: =IF(NETWORKDAYS(N30,O30,휴일!$A$2:$A$8)<0,"",NETWORKDAYS(N30,O30,휴일!$A$2:$A$8)) -> 0 | R30: =IFERROR(IF(M30>=$M$1,IF(NETWORKDAYS(L30,$M$1,휴일!$A$2:$A$8)>0,NETWORKDAYS(L30,$M$1,휴일!$A$2:$A$8),""),NETWORKDAYS(L30,M30,휴일!$A$2:$A$8)),"") | S30: =IF(IFERROR(IF(O30>=$M$1,IF(NETWORKDAYS(N30,$M$1,휴일!$A$2:$A$8)>0,NETWORKDAYS(N30,$M$1,휴일!$A$2:$A$8),""),NETWORKDAYS(N30,O30,휴일!$A$2:$A$8)),"")<0,"",IFERROR(IF(O30>=$M$1,IF(NETWORKDAYS(N30,$M$1,휴일!$A$2:$A$8)>0,NETWORKDAYS(N30,$M$1,휴일!$A$2:$A$8),""),NETWORKDAYS(N30,O30,휴일!$A$2:$A$8)),"")) -> 0 | T30: =IFERROR(R30/P30,0) -> 0 | U30: =IFERROR(S30/Q30,0) -> 0 | V30: =IF(OR(ISBLANK(S30),ISBLANK(P30),S30<=0,P30<=0),0,IF(S30="",0,1-(S30-P30)/P30)) -> 0 | W30: =V30-T30 -> 0
F31: [마일스톤] 전체 공정 통합·MVP 완성 (5개 스테이션 연결 검증) | H31: 정지훈 | I31: 박봉현 | J31: 문강호 | K31: MVP 빌드, 통합 점검표 | L31: 46328 | M31: 46328 | P31: =NETWORKDAYS(L31,M31,휴일!$A$2:$A$8) -> 1 | Q31: =IF(NETWORKDAYS(N31,O31,휴일!$A$2:$A$8)<0,"",NETWORKDAYS(N31,O31,휴일!$A$2:$A$8)) -> 0 | R31: =IFERROR(IF(M31>=$M$1,IF(NETWORKDAYS(L31,$M$1,휴일!$A$2:$A$8)>0,NETWORKDAYS(L31,$M$1,휴일!$A$2:$A$8),""),NETWORKDAYS(L31,M31,휴일!$A$2:$A$8)),"") | S31: =IF(IFERROR(IF(O31>=$M$1,IF(NETWORKDAYS(N31,$M$1,휴일!$A$2:$A$8)>0,NETWORKDAYS(N31,$M$1,휴일!$A$2:$A$8),""),NETWORKDAYS(N31,O31,휴일!$A$2:$A$8)),"")<0,"",IFERROR(IF(O31>=$M$1,IF(NETWORKDAYS(N31,$M$1,휴일!$A$2:$A$8)>0,NETWORKDAYS(N31,$M$1,휴일!$A$2:$A$8),""),NETWORKDAYS(N31,O31,휴일!$A$2:$A$8)),"")) -> 0 | T31: =IFERROR(R31/P31,0) -> 0 | U31: =IFERROR(S31/Q31,0) -> 0 | V31: =IF(OR(ISBLANK(S31),ISBLANK(P31),S31<=0,P31<=0),0,IF(S31="",0,1-(S31-P31)/P31)) -> 0 | W31: =V31-T31 -> 0
B32: 4 | C32: 0.2 | D32: 테스트 | F32: 단위 기능 테스트 (TC-01 ~ TC-09, TC-21) | H32: 문강호 | I32: 박봉현 | K32: 테스트 체크리스트 | L32: 46329 | M32: 46329 | P32: =NETWORKDAYS(L32,M32,휴일!$A$2:$A$8) -> 1 | Q32: =IF(NETWORKDAYS(N32,O32,휴일!$A$2:$A$8)<0,"",NETWORKDAYS(N32,O32,휴일!$A$2:$A$8)) -> 0 | R32: =IFERROR(IF(M32>=$M$1,IF(NETWORKDAYS(L32,$M$1,휴일!$A$2:$A$8)>0,NETWORKDAYS(L32,$M$1,휴일!$A$2:$A$8),""),NETWORKDAYS(L32,M32,휴일!$A$2:$A$8)),"") | S32: =IF(IFERROR(IF(O32>=$M$1,IF(NETWORKDAYS(N32,$M$1,휴일!$A$2:$A$8)>0,NETWORKDAYS(N32,$M$1,휴일!$A$2:$A$8),""),NETWORKDAYS(N32,O32,휴일!$A$2:$A$8)),"")<0,"",IFERROR(IF(O32>=$M$1,IF(NETWORKDAYS(N32,$M$1,휴일!$A$2:$A$8)>0,NETWORKDAYS(N32,$M$1,휴일!$A$2:$A$8),""),NETWORKDAYS(N32,O32,휴일!$A$2:$A$8)),"")) -> 0 | T32: =IFERROR(R32/P32,0) -> 0 | U32: =IFERROR(S32/Q32,0) -> 0 | V32: =IF(OR(ISBLANK(S32),ISBLANK(P32),S32<=0,P32<=0),0,IF(S32="",0,1-(S32-P32)/P32)) -> 0 | W32: =V32-T32 -> 0
F33: 송장면 판정 정확도 측정 (FR-03 ④, TC-03) | H33: 정지훈 | K33: 판정 정확도 기록 | L33: 46329 | M33: 46329 | P33: =NETWORKDAYS(L33,M33,휴일!$A$2:$A$8) -> 1 | Q33: =IF(NETWORKDAYS(N33,O33,휴일!$A$2:$A$8)<0,"",NETWORKDAYS(N33,O33,휴일!$A$2:$A$8)) -> 0 | R33: =IFERROR(IF(M33>=$M$1,IF(NETWORKDAYS(L33,$M$1,휴일!$A$2:$A$8)>0,NETWORKDAYS(L33,$M$1,휴일!$A$2:$A$8),""),NETWORKDAYS(L33,M33,휴일!$A$2:$A$8)),"") | S33: =IF(IFERROR(IF(O33>=$M$1,IF(NETWORKDAYS(N33,$M$1,휴일!$A$2:$A$8)>0,NETWORKDAYS(N33,$M$1,휴일!$A$2:$A$8),""),NETWORKDAYS(N33,O33,휴일!$A$2:$A$8)),"")<0,"",IFERROR(IF(O33>=$M$1,IF(NETWORKDAYS(N33,$M$1,휴일!$A$2:$A$8)>0,NETWORKDAYS(N33,$M$1,휴일!$A$2:$A$8),""),NETWORKDAYS(N33,O33,휴일!$A$2:$A$8)),"")) -> 0 | T33: =IFERROR(R33/P33,0) -> 0 | U33: =IFERROR(S33/Q33,0) -> 0 | V33: =IF(OR(ISBLANK(S33),ISBLANK(P33),S33<=0,P33<=0),0,IF(S33="",0,1-(S33-P33)/P33)) -> 0 | W33: =V33-T33 -> 0
F34: 판독 정확도 측정 (TC-04: 지역 코드 49/50, 전체 48/50) | H34: 정지훈 | K34: 정확도 측정 기록 | L34: 46329 | M34: 46329 | P34: =NETWORKDAYS(L34,M34,휴일!$A$2:$A$8) -> 1 | Q34: =IF(NETWORKDAYS(N34,O34,휴일!$A$2:$A$8)<0,"",NETWORKDAYS(N34,O34,휴일!$A$2:$A$8)) -> 0 | R34: =IFERROR(IF(M34>=$M$1,IF(NETWORKDAYS(L34,$M$1,휴일!$A$2:$A$8)>0,NETWORKDAYS(L34,$M$1,휴일!$A$2:$A$8),""),NETWORKDAYS(L34,M34,휴일!$A$2:$A$8)),"") | S34: =IF(IFERROR(IF(O34>=$M$1,IF(NETWORKDAYS(N34,$M$1,휴일!$A$2:$A$8)>0,NETWORKDAYS(N34,$M$1,휴일!$A$2:$A$8),""),NETWORKDAYS(N34,O34,휴일!$A$2:$A$8)),"")<0,"",IFERROR(IF(O34>=$M$1,IF(NETWORKDAYS(N34,$M$1,휴일!$A$2:$A$8)>0,NETWORKDAYS(N34,$M$1,휴일!$A$2:$A$8),""),NETWORKDAYS(N34,O34,휴일!$A$2:$A$8)),"")) -> 0 | T34: =IFERROR(R34/P34,0) -> 0 | U34: =IFERROR(S34/Q34,0) -> 0 | V34: =IF(OR(ISBLANK(S34),ISBLANK(P34),S34<=0,P34<=0),0,IF(S34="",0,1-(S34-P34)/P34)) -> 0 | W34: =V34-T34 -> 0
F35: 연속 운전 50개 테스트 (TC-13, TC-18) | H35: 박봉현 | K35: 연속 운전 로그 | L35: 46329 | M35: 46329 | P35: =NETWORKDAYS(L35,M35,휴일!$A$2:$A$8) -> 1 | Q35: =IF(NETWORKDAYS(N35,O35,휴일!$A$2:$A$8)<0,"",NETWORKDAYS(N35,O35,휴일!$A$2:$A$8)) -> 0 | R35: =IFERROR(IF(M35>=$M$1,IF(NETWORKDAYS(L35,$M$1,휴일!$A$2:$A$8)>0,NETWORKDAYS(L35,$M$1,휴일!$A$2:$A$8),""),NETWORKDAYS(L35,M35,휴일!$A$2:$A$8)),"") | S35: =IF(IFERROR(IF(O35>=$M$1,IF(NETWORKDAYS(N35,$M$1,휴일!$A$2:$A$8)>0,NETWORKDAYS(N35,$M$1,휴일!$A$2:$A$8),""),NETWORKDAYS(N35,O35,휴일!$A$2:$A$8)),"")<0,"",IFERROR(IF(O35>=$M$1,IF(NETWORKDAYS(N35,$M$1,휴일!$A$2:$A$8)>0,NETWORKDAYS(N35,$M$1,휴일!$A$2:$A$8),""),NETWORKDAYS(N35,O35,휴일!$A$2:$A$8)),"")) -> 0 | T35: =IFERROR(R35/P35,0) -> 0 | U35: =IFERROR(S35/Q35,0) -> 0 | V35: =IF(OR(ISBLANK(S35),ISBLANK(P35),S35<=0,P35<=0),0,IF(S35="",0,1-(S35-P35)/P35)) -> 0 | W35: =V35-T35 -> 0
F36: 성능·병렬 처리 측정 (TC-16, TC-17, TC-22) | H36: 박봉현 | K36: 성능 측정 기록 | L36: 46329 | M36: 46329 | P36: =NETWORKDAYS(L36,M36,휴일!$A$2:$A$8) -> 1 | Q36: =IF(NETWORKDAYS(N36,O36,휴일!$A$2:$A$8)<0,"",NETWORKDAYS(N36,O36,휴일!$A$2:$A$8)) -> 0 | R36: =IFERROR(IF(M36>=$M$1,IF(NETWORKDAYS(L36,$M$1,휴일!$A$2:$A$8)>0,NETWORKDAYS(L36,$M$1,휴일!$A$2:$A$8),""),NETWORKDAYS(L36,M36,휴일!$A$2:$A$8)),"") | S36: =IF(IFERROR(IF(O36>=$M$1,IF(NETWORKDAYS(N36,$M$1,휴일!$A$2:$A$8)>0,NETWORKDAYS(N36,$M$1,휴일!$A$2:$A$8),""),NETWORKDAYS(N36,O36,휴일!$A$2:$A$8)),"")<0,"",IFERROR(IF(O36>=$M$1,IF(NETWORKDAYS(N36,$M$1,휴일!$A$2:$A$8)>0,NETWORKDAYS(N36,$M$1,휴일!$A$2:$A$8),""),NETWORKDAYS(N36,O36,휴일!$A$2:$A$8)),"")) -> 0 | T36: =IFERROR(R36/P36,0) -> 0 | U36: =IFERROR(S36/Q36,0) -> 0 | V36: =IF(OR(ISBLANK(S36),ISBLANK(P36),S36<=0,P36<=0),0,IF(S36="",0,1-(S36-P36)/P36)) -> 0 | W36: =V36-T36 -> 0
F37: 빌드 실행·설정 변경 검사 (TC-19, TC-20) | H37: 문강호 | I37: 정지훈 | K37: 빌드 실행 영상 | L37: 46329 | M37: 46329 | P37: =NETWORKDAYS(L37,M37,휴일!$A$2:$A$8) -> 1 | Q37: =IF(NETWORKDAYS(N37,O37,휴일!$A$2:$A$8)<0,"",NETWORKDAYS(N37,O37,휴일!$A$2:$A$8)) -> 0 | R37: =IFERROR(IF(M37>=$M$1,IF(NETWORKDAYS(L37,$M$1,휴일!$A$2:$A$8)>0,NETWORKDAYS(L37,$M$1,휴일!$A$2:$A$8),""),NETWORKDAYS(L37,M37,휴일!$A$2:$A$8)),"") | S37: =IF(IFERROR(IF(O37>=$M$1,IF(NETWORKDAYS(N37,$M$1,휴일!$A$2:$A$8)>0,NETWORKDAYS(N37,$M$1,휴일!$A$2:$A$8),""),NETWORKDAYS(N37,O37,휴일!$A$2:$A$8)),"")<0,"",IFERROR(IF(O37>=$M$1,IF(NETWORKDAYS(N37,$M$1,휴일!$A$2:$A$8)>0,NETWORKDAYS(N37,$M$1,휴일!$A$2:$A$8),""),NETWORKDAYS(N37,O37,휴일!$A$2:$A$8)),"")) -> 0 | T37: =IFERROR(R37/P37,0) -> 0 | U37: =IFERROR(S37/Q37,0) -> 0 | V37: =IF(OR(ISBLANK(S37),ISBLANK(P37),S37<=0,P37<=0),0,IF(S37="",0,1-(S37-P37)/P37)) -> 0 | W37: =V37-T37 -> 0
B38: 5 | C38: 0.15 | D38: 발표준비 | F38: 테스트 결함 버그 수정 | H38: 박봉현 | I38: 문강호 | J38: 정지훈 | K38: 수정 이력 | L38: 46330 | M38: 46330 | P38: =NETWORKDAYS(L38,M38,휴일!$A$2:$A$8) -> 1 | Q38: =IF(NETWORKDAYS(N38,O38,휴일!$A$2:$A$8)<0,"",NETWORKDAYS(N38,O38,휴일!$A$2:$A$8)) -> 0 | R38: =IFERROR(IF(M38>=$M$1,IF(NETWORKDAYS(L38,$M$1,휴일!$A$2:$A$8)>0,NETWORKDAYS(L38,$M$1,휴일!$A$2:$A$8),""),NETWORKDAYS(L38,M38,휴일!$A$2:$A$8)),"") | S38: =IF(IFERROR(IF(O38>=$M$1,IF(NETWORKDAYS(N38,$M$1,휴일!$A$2:$A$8)>0,NETWORKDAYS(N38,$M$1,휴일!$A$2:$A$8),""),NETWORKDAYS(N38,O38,휴일!$A$2:$A$8)),"")<0,"",IFERROR(IF(O38>=$M$1,IF(NETWORKDAYS(N38,$M$1,휴일!$A$2:$A$8)>0,NETWORKDAYS(N38,$M$1,휴일!$A$2:$A$8),""),NETWORKDAYS(N38,O38,휴일!$A$2:$A$8)),"")) -> 0 | T38: =IFERROR(R38/P38,0) -> 0 | U38: =IFERROR(S38/Q38,0) -> 0 | V38: =IF(OR(ISBLANK(S38),ISBLANK(P38),S38<=0,P38<=0),0,IF(S38="",0,1-(S38-P38)/P38)) -> 0 | W38: =V38-T38 -> 0
F39: 시연 영상 촬영·편집 | H39: 문강호 | K39: 시연 영상 | L39: 46330 | M39: 46330 | P39: =NETWORKDAYS(L39,M39,휴일!$A$2:$A$8) -> 1 | Q39: =IF(NETWORKDAYS(N39,O39,휴일!$A$2:$A$8)<0,"",NETWORKDAYS(N39,O39,휴일!$A$2:$A$8)) -> 0 | R39: =IFERROR(IF(M39>=$M$1,IF(NETWORKDAYS(L39,$M$1,휴일!$A$2:$A$8)>0,NETWORKDAYS(L39,$M$1,휴일!$A$2:$A$8),""),NETWORKDAYS(L39,M39,휴일!$A$2:$A$8)),"") | S39: =IF(IFERROR(IF(O39>=$M$1,IF(NETWORKDAYS(N39,$M$1,휴일!$A$2:$A$8)>0,NETWORKDAYS(N39,$M$1,휴일!$A$2:$A$8),""),NETWORKDAYS(N39,O39,휴일!$A$2:$A$8)),"")<0,"",IFERROR(IF(O39>=$M$1,IF(NETWORKDAYS(N39,$M$1,휴일!$A$2:$A$8)>0,NETWORKDAYS(N39,$M$1,휴일!$A$2:$A$8),""),NETWORKDAYS(N39,O39,휴일!$A$2:$A$8)),"")) -> 0 | T39: =IFERROR(R39/P39,0) -> 0 | U39: =IFERROR(S39/Q39,0) -> 0 | V39: =IF(OR(ISBLANK(S39),ISBLANK(P39),S39<=0,P39<=0),0,IF(S39="",0,1-(S39-P39)/P39)) -> 0 | W39: =V39-T39 -> 0
F40: 발표 PPT 제작 (11/3 초안 병행) | H40: 정지훈 | I40: 박봉현 | K40: PPT 파일 | L40: 46329 | M40: 46330 | P40: =NETWORKDAYS(L40,M40,휴일!$A$2:$A$8) -> 2 | Q40: =IF(NETWORKDAYS(N40,O40,휴일!$A$2:$A$8)<0,"",NETWORKDAYS(N40,O40,휴일!$A$2:$A$8)) -> 0 | R40: =IFERROR(IF(M40>=$M$1,IF(NETWORKDAYS(L40,$M$1,휴일!$A$2:$A$8)>0,NETWORKDAYS(L40,$M$1,휴일!$A$2:$A$8),""),NETWORKDAYS(L40,M40,휴일!$A$2:$A$8)),"") | S40: =IF(IFERROR(IF(O40>=$M$1,IF(NETWORKDAYS(N40,$M$1,휴일!$A$2:$A$8)>0,NETWORKDAYS(N40,$M$1,휴일!$A$2:$A$8),""),NETWORKDAYS(N40,O40,휴일!$A$2:$A$8)),"")<0,"",IFERROR(IF(O40>=$M$1,IF(NETWORKDAYS(N40,$M$1,휴일!$A$2:$A$8)>0,NETWORKDAYS(N40,$M$1,휴일!$A$2:$A$8),""),NETWORKDAYS(N40,O40,휴일!$A$2:$A$8)),"")) -> 0 | T40: =IFERROR(R40/P40,0) -> 0 | U40: =IFERROR(S40/Q40,0) -> 0 | V40: =IF(OR(ISBLANK(S40),ISBLANK(P40),S40<=0,P40<=0),0,IF(S40="",0,1-(S40-P40)/P40)) -> 0 | W40: =V40-T40 -> 0
F41: README·산출물 정리 | H41: 박봉현 | K41: README 파일 | L41: 46330 | M41: 46330 | P41: =NETWORKDAYS(L41,M41,휴일!$A$2:$A$8) -> 1 | Q41: =IF(NETWORKDAYS(N41,O41,휴일!$A$2:$A$8)<0,"",NETWORKDAYS(N41,O41,휴일!$A$2:$A$8)) -> 0 | R41: =IFERROR(IF(M41>=$M$1,IF(NETWORKDAYS(L41,$M$1,휴일!$A$2:$A$8)>0,NETWORKDAYS(L41,$M$1,휴일!$A$2:$A$8),""),NETWORKDAYS(L41,M41,휴일!$A$2:$A$8)),"") | S41: =IF(IFERROR(IF(O41>=$M$1,IF(NETWORKDAYS(N41,$M$1,휴일!$A$2:$A$8)>0,NETWORKDAYS(N41,$M$1,휴일!$A$2:$A$8),""),NETWORKDAYS(N41,O41,휴일!$A$2:$A$8)),"")<0,"",IFERROR(IF(O41>=$M$1,IF(NETWORKDAYS(N41,$M$1,휴일!$A$2:$A$8)>0,NETWORKDAYS(N41,$M$1,휴일!$A$2:$A$8),""),NETWORKDAYS(N41,O41,휴일!$A$2:$A$8)),"")) -> 0 | T41: =IFERROR(R41/P41,0) -> 0 | U41: =IFERROR(S41/Q41,0) -> 0 | V41: =IF(OR(ISBLANK(S41),ISBLANK(P41),S41<=0,P41<=0),0,IF(S41="",0,1-(S41-P41)/P41)) -> 0 | W41: =V41-T41 -> 0
...

Sheet 휴일
A1: 휴일
A2: 46220 | B2: 제헌절
